[2023-08-04T10:37:50.801+0000] {taskinstance.py:1103} INFO - Dependencies all met for dep_context=non-requeueable deps ti=<TaskInstance: toronto_real_estate_etl.createTables manual__2023-08-04T09:33:43.522776+00:00 [queued]>
[2023-08-04T10:37:50.807+0000] {taskinstance.py:1103} INFO - Dependencies all met for dep_context=requeueable deps ti=<TaskInstance: toronto_real_estate_etl.createTables manual__2023-08-04T09:33:43.522776+00:00 [queued]>
[2023-08-04T10:37:50.807+0000] {taskinstance.py:1308} INFO - Starting attempt 3 of 3
[2023-08-04T10:37:50.817+0000] {taskinstance.py:1327} INFO - Executing <Task(PythonOperator): createTables> on 2023-08-04 09:33:43.522776+00:00
[2023-08-04T10:37:50.822+0000] {standard_task_runner.py:57} INFO - Started process 1348 to run task
[2023-08-04T10:37:50.824+0000] {standard_task_runner.py:84} INFO - Running: ['***', 'tasks', 'run', 'toronto_real_estate_etl', 'createTables', 'manual__2023-08-04T09:33:43.522776+00:00', '--job-id', '110', '--raw', '--subdir', 'DAGS_FOLDER/etl.py', '--cfg-path', '/tmp/tmpfi158n7d']
[2023-08-04T10:37:50.826+0000] {standard_task_runner.py:85} INFO - Job 110: Subtask createTables
[2023-08-04T10:37:50.857+0000] {task_command.py:410} INFO - Running <TaskInstance: toronto_real_estate_etl.createTables manual__2023-08-04T09:33:43.522776+00:00 [running]> on host e5187b3c4256
[2023-08-04T10:37:50.905+0000] {taskinstance.py:1547} INFO - Exporting env vars: AIRFLOW_CTX_DAG_OWNER='***' AIRFLOW_CTX_DAG_ID='toronto_real_estate_etl' AIRFLOW_CTX_TASK_ID='createTables' AIRFLOW_CTX_EXECUTION_DATE='2023-08-04T09:33:43.522776+00:00' AIRFLOW_CTX_TRY_NUMBER='3' AIRFLOW_CTX_DAG_RUN_ID='manual__2023-08-04T09:33:43.522776+00:00'
[2023-08-04T10:37:53.459+0000] {taskinstance.py:1824} ERROR - Task failed with exception
Traceback (most recent call last):
  File "/home/airflow/.local/lib/python3.7/site-packages/airflow/operators/python.py", line 181, in execute
    return_value = self.execute_callable()
  File "/home/airflow/.local/lib/python3.7/site-packages/airflow/operators/python.py", line 198, in execute_callable
    return self.python_callable(*self.op_args, **self.op_kwargs)
  File "/opt/airflow/dags/src/main.py", line 48, in createRedShiftTables
    createTables()
  File "/opt/airflow/dags/src/Load.py", line 139, in createTables
    cur.execute(create_temp_table)
psycopg2.errors.DuplicateTable: Relation "staging_table" already exists

[2023-08-04T10:37:53.465+0000] {taskinstance.py:1350} INFO - Marking task as FAILED. dag_id=toronto_real_estate_etl, task_id=createTables, execution_date=20230804T093343, start_date=20230804T103750, end_date=20230804T103753
[2023-08-04T10:37:53.473+0000] {standard_task_runner.py:109} ERROR - Failed to execute job 110 for task createTables (Relation "staging_table" already exists
; 1348)
[2023-08-04T10:37:53.490+0000] {local_task_job_runner.py:225} INFO - Task exited with return code 1
[2023-08-04T10:37:53.507+0000] {taskinstance.py:2653} INFO - 0 downstream tasks scheduled from follow-on schedule check
