[2023-08-01T11:30:01.182+0000] {taskinstance.py:1103} INFO - Dependencies all met for dep_context=non-requeueable deps ti=<TaskInstance: toronto_real_estate_etl.StagetoFinal manual__2023-08-01T11:16:42.810577+00:00 [queued]>
[2023-08-01T11:30:01.191+0000] {taskinstance.py:1103} INFO - Dependencies all met for dep_context=requeueable deps ti=<TaskInstance: toronto_real_estate_etl.StagetoFinal manual__2023-08-01T11:16:42.810577+00:00 [queued]>
[2023-08-01T11:30:01.191+0000] {taskinstance.py:1308} INFO - Starting attempt 2 of 2
[2023-08-01T11:30:01.202+0000] {taskinstance.py:1327} INFO - Executing <Task(PythonOperator): StagetoFinal> on 2023-08-01 11:16:42.810577+00:00
[2023-08-01T11:30:01.207+0000] {standard_task_runner.py:57} INFO - Started process 782 to run task
[2023-08-01T11:30:01.210+0000] {standard_task_runner.py:84} INFO - Running: ['***', 'tasks', 'run', 'toronto_real_estate_etl', 'StagetoFinal', 'manual__2023-08-01T11:16:42.810577+00:00', '--job-id', '81', '--raw', '--subdir', 'DAGS_FOLDER/etl.py', '--cfg-path', '/tmp/tmpn1vf59uc']
[2023-08-01T11:30:01.212+0000] {standard_task_runner.py:85} INFO - Job 81: Subtask StagetoFinal
[2023-08-01T11:30:01.247+0000] {task_command.py:410} INFO - Running <TaskInstance: toronto_real_estate_etl.StagetoFinal manual__2023-08-01T11:16:42.810577+00:00 [running]> on host e5187b3c4256
[2023-08-01T11:30:01.312+0000] {taskinstance.py:1547} INFO - Exporting env vars: AIRFLOW_CTX_DAG_OWNER='***' AIRFLOW_CTX_DAG_ID='toronto_real_estate_etl' AIRFLOW_CTX_TASK_ID='StagetoFinal' AIRFLOW_CTX_EXECUTION_DATE='2023-08-01T11:16:42.810577+00:00' AIRFLOW_CTX_TRY_NUMBER='2' AIRFLOW_CTX_DAG_RUN_ID='manual__2023-08-01T11:16:42.810577+00:00'
[2023-08-01T11:30:03.915+0000] {taskinstance.py:1824} ERROR - Task failed with exception
Traceback (most recent call last):
  File "/home/airflow/.local/lib/python3.7/site-packages/airflow/operators/python.py", line 181, in execute
    return_value = self.execute_callable()
  File "/home/airflow/.local/lib/python3.7/site-packages/airflow/operators/python.py", line 198, in execute_callable
    return self.python_callable(*self.op_args, **self.op_kwargs)
  File "/opt/airflow/dags/src/main.py", line 103, in insertIntoFinalRedshiftTable
    insertIntoFinal()
  File "/opt/airflow/dags/src/Load.py", line 161, in insertIntoFinal
    cur.execute(delete_from_table)
psycopg2.errors.UndefinedTable: relation "stage_table" does not exist

[2023-08-01T11:30:03.920+0000] {taskinstance.py:1350} INFO - Marking task as FAILED. dag_id=toronto_real_estate_etl, task_id=StagetoFinal, execution_date=20230801T111642, start_date=20230801T113001, end_date=20230801T113003
[2023-08-01T11:30:03.929+0000] {standard_task_runner.py:109} ERROR - Failed to execute job 81 for task StagetoFinal (relation "stage_table" does not exist
; 782)
[2023-08-01T11:30:03.957+0000] {local_task_job_runner.py:225} INFO - Task exited with return code 1
[2023-08-01T11:30:03.968+0000] {taskinstance.py:2653} INFO - 0 downstream tasks scheduled from follow-on schedule check
