[2023-07-28T16:15:03.505+0000] {taskinstance.py:1103} INFO - Dependencies all met for dep_context=non-requeueable deps ti=<TaskInstance: toronto_real_estate_etl.Transform manual__2023-07-28T16:00:30.036848+00:00 [queued]>
[2023-07-28T16:15:03.511+0000] {taskinstance.py:1103} INFO - Dependencies all met for dep_context=requeueable deps ti=<TaskInstance: toronto_real_estate_etl.Transform manual__2023-07-28T16:00:30.036848+00:00 [queued]>
[2023-07-28T16:15:03.511+0000] {taskinstance.py:1308} INFO - Starting attempt 2 of 2
[2023-07-28T16:15:03.521+0000] {taskinstance.py:1327} INFO - Executing <Task(PythonOperator): Transform> on 2023-07-28 16:00:30.036848+00:00
[2023-07-28T16:15:03.525+0000] {standard_task_runner.py:57} INFO - Started process 1124 to run task
[2023-07-28T16:15:03.528+0000] {standard_task_runner.py:84} INFO - Running: ['***', 'tasks', 'run', 'toronto_real_estate_etl', 'Transform', 'manual__2023-07-28T16:00:30.036848+00:00', '--job-id', '55', '--raw', '--subdir', 'DAGS_FOLDER/etl.py', '--cfg-path', '/tmp/tmpy60tttd0']
[2023-07-28T16:15:03.530+0000] {standard_task_runner.py:85} INFO - Job 55: Subtask Transform
[2023-07-28T16:15:03.563+0000] {task_command.py:410} INFO - Running <TaskInstance: toronto_real_estate_etl.Transform manual__2023-07-28T16:00:30.036848+00:00 [running]> on host e5187b3c4256
[2023-07-28T16:15:03.628+0000] {taskinstance.py:1547} INFO - Exporting env vars: AIRFLOW_CTX_DAG_OWNER='***' AIRFLOW_CTX_DAG_ID='toronto_real_estate_etl' AIRFLOW_CTX_TASK_ID='Transform' AIRFLOW_CTX_EXECUTION_DATE='2023-07-28T16:00:30.036848+00:00' AIRFLOW_CTX_TRY_NUMBER='2' AIRFLOW_CTX_DAG_RUN_ID='manual__2023-07-28T16:00:30.036848+00:00'
[2023-07-28T16:15:03.629+0000] {taskinstance.py:1824} ERROR - Task failed with exception
Traceback (most recent call last):
  File "/home/airflow/.local/lib/python3.7/site-packages/airflow/operators/python.py", line 181, in execute
    return_value = self.execute_callable()
  File "/home/airflow/.local/lib/python3.7/site-packages/airflow/operators/python.py", line 198, in execute_callable
    return self.python_callable(*self.op_args, **self.op_kwargs)
  File "/opt/airflow/dags/src/main.py", line 88, in transform
    t.transform()
TypeError: transform() missing 1 required positional argument: 'filename'
[2023-07-28T16:15:03.636+0000] {taskinstance.py:1350} INFO - Marking task as FAILED. dag_id=toronto_real_estate_etl, task_id=Transform, execution_date=20230728T160030, start_date=20230728T161503, end_date=20230728T161503
[2023-07-28T16:15:03.644+0000] {standard_task_runner.py:109} ERROR - Failed to execute job 55 for task Transform (transform() missing 1 required positional argument: 'filename'; 1124)
[2023-07-28T16:15:03.660+0000] {local_task_job_runner.py:225} INFO - Task exited with return code 1
[2023-07-28T16:15:03.678+0000] {taskinstance.py:2653} INFO - 0 downstream tasks scheduled from follow-on schedule check
