[2023-08-01T11:06:04.771+0000] {taskinstance.py:1103} INFO - Dependencies all met for dep_context=non-requeueable deps ti=<TaskInstance: toronto_real_estate_etl.Extract scheduled__2023-07-28T00:00:00+00:00 [queued]>
[2023-08-01T11:06:04.777+0000] {taskinstance.py:1103} INFO - Dependencies all met for dep_context=requeueable deps ti=<TaskInstance: toronto_real_estate_etl.Extract scheduled__2023-07-28T00:00:00+00:00 [queued]>
[2023-08-01T11:06:04.777+0000] {taskinstance.py:1308} INFO - Starting attempt 1 of 1
[2023-08-01T11:06:04.786+0000] {taskinstance.py:1327} INFO - Executing <Task(PythonOperator): Extract> on 2023-07-28 00:00:00+00:00
[2023-08-01T11:06:04.789+0000] {standard_task_runner.py:57} INFO - Started process 330 to run task
[2023-08-01T11:06:04.792+0000] {standard_task_runner.py:84} INFO - Running: ['***', 'tasks', 'run', 'toronto_real_estate_etl', 'Extract', 'scheduled__2023-07-28T00:00:00+00:00', '--job-id', '69', '--raw', '--subdir', 'DAGS_FOLDER/etl.py', '--cfg-path', '/tmp/tmpysco_n5g']
[2023-08-01T11:06:04.794+0000] {standard_task_runner.py:85} INFO - Job 69: Subtask Extract
[2023-08-01T11:06:04.827+0000] {task_command.py:410} INFO - Running <TaskInstance: toronto_real_estate_etl.Extract scheduled__2023-07-28T00:00:00+00:00 [running]> on host e5187b3c4256
[2023-08-01T11:06:04.877+0000] {taskinstance.py:1547} INFO - Exporting env vars: AIRFLOW_CTX_DAG_OWNER='***' AIRFLOW_CTX_DAG_ID='toronto_real_estate_etl' AIRFLOW_CTX_TASK_ID='Extract' AIRFLOW_CTX_EXECUTION_DATE='2023-07-28T00:00:00+00:00' AIRFLOW_CTX_TRY_NUMBER='1' AIRFLOW_CTX_DAG_RUN_ID='scheduled__2023-07-28T00:00:00+00:00'
[2023-08-01T11:06:04.878+0000] {main.py:32} INFO - https://www.kijiji.ca/b-apartments-condos/page-1/c37l1700273
[2023-08-01T11:10:21.403+0000] {local_task_job_runner.py:292} WARNING - State of this instance has been externally set to restarting. Terminating instance.
[2023-08-01T11:10:21.404+0000] {process_utils.py:135} INFO - Sending Signals.SIGTERM to group 330. PIDs of all processes in the group: [330]
[2023-08-01T11:10:21.404+0000] {process_utils.py:86} INFO - Sending the signal Signals.SIGTERM to group 330
[2023-08-01T11:10:21.405+0000] {taskinstance.py:1517} ERROR - Received SIGTERM. Terminating subprocesses.
[2023-08-01T11:10:21.412+0000] {taskinstance.py:1824} ERROR - Task failed with exception
Traceback (most recent call last):
  File "/home/airflow/.local/lib/python3.7/site-packages/airflow/operators/python.py", line 181, in execute
    return_value = self.execute_callable()
  File "/home/airflow/.local/lib/python3.7/site-packages/airflow/operators/python.py", line 198, in execute_callable
    return self.python_callable(*self.op_args, **self.op_kwargs)
  File "/opt/airflow/dags/src/main.py", line 70, in extract
    e.getListings(2)
  File "/opt/airflow/dags/src/main.py", line 45, in getListings
    s.getHeaderDetails()
  File "/opt/airflow/dags/src/Scrape.py", line 42, in getHeaderDetails
    r =session.get(self.link,headers=headers)
  File "/home/airflow/.local/lib/python3.7/site-packages/requests/sessions.py", line 602, in get
    return self.request("GET", url, **kwargs)
  File "/home/airflow/.local/lib/python3.7/site-packages/requests/sessions.py", line 589, in request
    resp = self.send(prep, **send_kwargs)
  File "/home/airflow/.local/lib/python3.7/site-packages/requests/sessions.py", line 703, in send
    r = adapter.send(request, **kwargs)
  File "/home/airflow/.local/lib/python3.7/site-packages/requests/adapters.py", line 497, in send
    chunked=chunked,
  File "/home/airflow/.local/lib/python3.7/site-packages/urllib3/connectionpool.py", line 721, in urlopen
    chunked=chunked,
  File "/home/airflow/.local/lib/python3.7/site-packages/urllib3/connectionpool.py", line 466, in _make_request
    six.raise_from(e, None)
  File "<string>", line 3, in raise_from
  File "/home/airflow/.local/lib/python3.7/site-packages/urllib3/connectionpool.py", line 461, in _make_request
    httplib_response = conn.getresponse()
  File "/usr/local/lib/python3.7/http/client.py", line 1373, in getresponse
    response.begin()
  File "/usr/local/lib/python3.7/http/client.py", line 319, in begin
    version, status, reason = self._read_status()
  File "/usr/local/lib/python3.7/http/client.py", line 280, in _read_status
    line = str(self.fp.readline(_MAXLINE + 1), "iso-8859-1")
  File "/usr/local/lib/python3.7/socket.py", line 589, in readinto
    return self._sock.recv_into(b)
  File "/usr/local/lib/python3.7/ssl.py", line 1071, in recv_into
    return self.read(nbytes, buffer)
  File "/usr/local/lib/python3.7/ssl.py", line 929, in read
    return self._sslobj.read(len, buffer)
  File "/home/airflow/.local/lib/python3.7/site-packages/airflow/models/taskinstance.py", line 1519, in signal_handler
    raise AirflowException("Task received SIGTERM signal")
airflow.exceptions.AirflowException: Task received SIGTERM signal
[2023-08-01T11:10:21.418+0000] {taskinstance.py:1350} INFO - Marking task as UP_FOR_RETRY. dag_id=toronto_real_estate_etl, task_id=Extract, execution_date=20230728T000000, start_date=20230801T110604, end_date=20230801T111021
[2023-08-01T11:10:21.427+0000] {standard_task_runner.py:109} ERROR - Failed to execute job 69 for task Extract (Task received SIGTERM signal; 330)
[2023-08-01T11:10:21.457+0000] {process_utils.py:79} INFO - Process psutil.Process(pid=330, status='terminated', exitcode=1, started='11:06:03') (330) terminated with exit code 1
[2023-08-01T11:10:43.597+0000] {taskinstance.py:1103} INFO - Dependencies all met for dep_context=non-requeueable deps ti=<TaskInstance: toronto_real_estate_etl.Extract scheduled__2023-07-28T00:00:00+00:00 [queued]>
[2023-08-01T11:10:43.604+0000] {taskinstance.py:1103} INFO - Dependencies all met for dep_context=requeueable deps ti=<TaskInstance: toronto_real_estate_etl.Extract scheduled__2023-07-28T00:00:00+00:00 [queued]>
[2023-08-01T11:10:43.605+0000] {taskinstance.py:1308} INFO - Starting attempt 1 of 1
[2023-08-01T11:10:43.616+0000] {taskinstance.py:1327} INFO - Executing <Task(PythonOperator): Extract> on 2023-07-28 00:00:00+00:00
[2023-08-01T11:10:43.621+0000] {standard_task_runner.py:57} INFO - Started process 413 to run task
[2023-08-01T11:10:43.623+0000] {standard_task_runner.py:84} INFO - Running: ['***', 'tasks', 'run', 'toronto_real_estate_etl', 'Extract', 'scheduled__2023-07-28T00:00:00+00:00', '--job-id', '70', '--raw', '--subdir', 'DAGS_FOLDER/etl.py', '--cfg-path', '/tmp/tmpn85f90eu']
[2023-08-01T11:10:43.625+0000] {standard_task_runner.py:85} INFO - Job 70: Subtask Extract
[2023-08-01T11:10:43.663+0000] {task_command.py:410} INFO - Running <TaskInstance: toronto_real_estate_etl.Extract scheduled__2023-07-28T00:00:00+00:00 [running]> on host e5187b3c4256
[2023-08-01T11:10:43.727+0000] {taskinstance.py:1547} INFO - Exporting env vars: AIRFLOW_CTX_DAG_OWNER='***' AIRFLOW_CTX_DAG_ID='toronto_real_estate_etl' AIRFLOW_CTX_TASK_ID='Extract' AIRFLOW_CTX_EXECUTION_DATE='2023-07-28T00:00:00+00:00' AIRFLOW_CTX_TRY_NUMBER='1' AIRFLOW_CTX_DAG_RUN_ID='scheduled__2023-07-28T00:00:00+00:00'
[2023-08-01T11:10:43.729+0000] {main.py:32} INFO - https://www.kijiji.ca/b-apartments-condos/page-1/c37l1700273
[2023-08-01T11:12:14.341+0000] {local_task_job_runner.py:292} WARNING - State of this instance has been externally set to queued. Terminating instance.
[2023-08-01T11:12:14.342+0000] {process_utils.py:135} INFO - Sending Signals.SIGTERM to group 413. PIDs of all processes in the group: [413]
[2023-08-01T11:12:14.342+0000] {process_utils.py:86} INFO - Sending the signal Signals.SIGTERM to group 413
[2023-08-01T11:12:14.342+0000] {taskinstance.py:1517} ERROR - Received SIGTERM. Terminating subprocesses.
[2023-08-01T11:12:14.349+0000] {taskinstance.py:1824} ERROR - Task failed with exception
Traceback (most recent call last):
  File "/home/airflow/.local/lib/python3.7/site-packages/airflow/operators/python.py", line 181, in execute
    return_value = self.execute_callable()
  File "/home/airflow/.local/lib/python3.7/site-packages/airflow/operators/python.py", line 198, in execute_callable
    return self.python_callable(*self.op_args, **self.op_kwargs)
  File "/opt/airflow/dags/src/main.py", line 70, in extract
    e.getListings(2)
  File "/opt/airflow/dags/src/main.py", line 50, in getListings
    time.sleep(3)
  File "/home/airflow/.local/lib/python3.7/site-packages/airflow/models/taskinstance.py", line 1519, in signal_handler
    raise AirflowException("Task received SIGTERM signal")
airflow.exceptions.AirflowException: Task received SIGTERM signal
[2023-08-01T11:12:14.351+0000] {taskinstance.py:1350} INFO - Marking task as FAILED. dag_id=toronto_real_estate_etl, task_id=Extract, execution_date=20230728T000000, start_date=, end_date=20230801T111214
[2023-08-01T11:12:14.358+0000] {standard_task_runner.py:109} ERROR - Failed to execute job 70 for task Extract ((psycopg2.errors.UniqueViolation) duplicate key value violates unique constraint "dag_run_dag_id_execution_date_key"
DETAIL:  Key (dag_id, execution_date)=(toronto_real_estate_etl, 2023-07-28 00:00:00+00) already exists.

[SQL: INSERT INTO dag_run (id, dag_id, queued_at, execution_date, start_date, end_date, state, run_id, creating_job_id, external_trigger, run_type, conf, data_interval_start, data_interval_end, last_scheduling_decision, dag_hash, log_template_id, updated_at) VALUES (%(id)s, %(dag_id)s, %(queued_at)s, %(execution_date)s, %(start_date)s, %(end_date)s, %(state)s, %(run_id)s, %(creating_job_id)s, %(external_trigger)s, %(run_type)s, %(conf)s, %(data_interval_start)s, %(data_interval_end)s, %(last_scheduling_decision)s, %(dag_hash)s, %(log_template_id)s, %(updated_at)s)]
[parameters: {'id': 19, 'dag_id': 'toronto_real_estate_etl', 'queued_at': datetime.datetime(2023, 8, 1, 11, 10, 43, 198521, tzinfo=Timezone('UTC')), 'execution_date': datetime.datetime(2023, 7, 28, 0, 0, tzinfo=Timezone('UTC')), 'start_date': datetime.datetime(2023, 8, 1, 11, 10, 43, 209892, tzinfo=Timezone('UTC')), 'end_date': None, 'state': 'running', 'run_id': 'scheduled__2023-07-28T00:00:00+00:00', 'creating_job_id': 67, 'external_trigger': False, 'run_type': 'scheduled', 'conf': <psycopg2.extensions.Binary object at 0x7f9ee82a8120>, 'data_interval_start': datetime.datetime(2023, 7, 28, 0, 0, tzinfo=Timezone('UTC')), 'data_interval_end': datetime.datetime(2023, 7, 29, 0, 0, tzinfo=Timezone('UTC')), 'last_scheduling_decision': datetime.datetime(2023, 8, 1, 11, 10, 43, 291836, tzinfo=Timezone('UTC')), 'dag_hash': '434d276ae0621b687df64482f937d17f', 'log_template_id': 2, 'updated_at': datetime.datetime(2023, 8, 1, 11, 10, 43, 296734, tzinfo=Timezone('UTC'))}]
(Background on this error at: https://sqlalche.me/e/14/gkpj); 413)
[2023-08-01T11:12:14.369+0000] {process_utils.py:79} INFO - Process psutil.Process(pid=413, status='terminated', exitcode=1, started='11:10:42') (413) terminated with exit code 1
[2023-08-01T11:12:16.338+0000] {taskinstance.py:1103} INFO - Dependencies all met for dep_context=non-requeueable deps ti=<TaskInstance: toronto_real_estate_etl.Extract scheduled__2023-07-28T00:00:00+00:00 [queued]>
[2023-08-01T11:12:16.344+0000] {taskinstance.py:1103} INFO - Dependencies all met for dep_context=requeueable deps ti=<TaskInstance: toronto_real_estate_etl.Extract scheduled__2023-07-28T00:00:00+00:00 [queued]>
[2023-08-01T11:12:16.345+0000] {taskinstance.py:1308} INFO - Starting attempt 1 of 1
[2023-08-01T11:12:16.354+0000] {taskinstance.py:1327} INFO - Executing <Task(PythonOperator): Extract> on 2023-07-28 00:00:00+00:00
[2023-08-01T11:12:16.358+0000] {standard_task_runner.py:57} INFO - Started process 442 to run task
[2023-08-01T11:12:16.361+0000] {standard_task_runner.py:84} INFO - Running: ['***', 'tasks', 'run', 'toronto_real_estate_etl', 'Extract', 'scheduled__2023-07-28T00:00:00+00:00', '--job-id', '71', '--raw', '--subdir', 'DAGS_FOLDER/etl.py', '--cfg-path', '/tmp/tmpgzb0a47w']
[2023-08-01T11:12:16.362+0000] {standard_task_runner.py:85} INFO - Job 71: Subtask Extract
[2023-08-01T11:12:16.396+0000] {task_command.py:410} INFO - Running <TaskInstance: toronto_real_estate_etl.Extract scheduled__2023-07-28T00:00:00+00:00 [running]> on host e5187b3c4256
[2023-08-01T11:12:16.445+0000] {taskinstance.py:1547} INFO - Exporting env vars: AIRFLOW_CTX_DAG_OWNER='***' AIRFLOW_CTX_DAG_ID='toronto_real_estate_etl' AIRFLOW_CTX_TASK_ID='Extract' AIRFLOW_CTX_EXECUTION_DATE='2023-07-28T00:00:00+00:00' AIRFLOW_CTX_TRY_NUMBER='1' AIRFLOW_CTX_DAG_RUN_ID='scheduled__2023-07-28T00:00:00+00:00'
[2023-08-01T11:12:16.446+0000] {main.py:32} INFO - https://www.kijiji.ca/b-apartments-condos/page-1/c37l1700273
[2023-08-01T11:14:01.979+0000] {local_task_job_runner.py:292} WARNING - State of this instance has been externally set to None. Terminating instance.
[2023-08-01T11:14:01.980+0000] {process_utils.py:135} INFO - Sending Signals.SIGTERM to group 442. PIDs of all processes in the group: [442]
[2023-08-01T11:14:01.980+0000] {process_utils.py:86} INFO - Sending the signal Signals.SIGTERM to group 442
[2023-08-01T11:14:01.980+0000] {taskinstance.py:1517} ERROR - Received SIGTERM. Terminating subprocesses.
[2023-08-01T11:14:01.989+0000] {taskinstance.py:1824} ERROR - Task failed with exception
Traceback (most recent call last):
  File "/home/airflow/.local/lib/python3.7/site-packages/airflow/operators/python.py", line 181, in execute
    return_value = self.execute_callable()
  File "/home/airflow/.local/lib/python3.7/site-packages/airflow/operators/python.py", line 198, in execute_callable
    return self.python_callable(*self.op_args, **self.op_kwargs)
  File "/opt/airflow/dags/src/main.py", line 70, in extract
    e.getListings(2)
  File "/opt/airflow/dags/src/main.py", line 45, in getListings
    s.getHeaderDetails()
  File "/opt/airflow/dags/src/Scrape.py", line 42, in getHeaderDetails
    r =session.get(self.link,headers=headers)
  File "/home/airflow/.local/lib/python3.7/site-packages/requests/sessions.py", line 602, in get
    return self.request("GET", url, **kwargs)
  File "/home/airflow/.local/lib/python3.7/site-packages/requests/sessions.py", line 589, in request
    resp = self.send(prep, **send_kwargs)
  File "/home/airflow/.local/lib/python3.7/site-packages/requests/sessions.py", line 703, in send
    r = adapter.send(request, **kwargs)
  File "/home/airflow/.local/lib/python3.7/site-packages/requests/adapters.py", line 497, in send
    chunked=chunked,
  File "/home/airflow/.local/lib/python3.7/site-packages/urllib3/connectionpool.py", line 721, in urlopen
    chunked=chunked,
  File "/home/airflow/.local/lib/python3.7/site-packages/urllib3/connectionpool.py", line 466, in _make_request
    six.raise_from(e, None)
  File "<string>", line 3, in raise_from
  File "/home/airflow/.local/lib/python3.7/site-packages/urllib3/connectionpool.py", line 461, in _make_request
    httplib_response = conn.getresponse()
  File "/usr/local/lib/python3.7/http/client.py", line 1373, in getresponse
    response.begin()
  File "/usr/local/lib/python3.7/http/client.py", line 319, in begin
    version, status, reason = self._read_status()
  File "/usr/local/lib/python3.7/http/client.py", line 280, in _read_status
    line = str(self.fp.readline(_MAXLINE + 1), "iso-8859-1")
  File "/usr/local/lib/python3.7/socket.py", line 589, in readinto
    return self._sock.recv_into(b)
  File "/usr/local/lib/python3.7/ssl.py", line 1071, in recv_into
    return self.read(nbytes, buffer)
  File "/usr/local/lib/python3.7/ssl.py", line 929, in read
    return self._sslobj.read(len, buffer)
  File "/home/airflow/.local/lib/python3.7/site-packages/airflow/models/taskinstance.py", line 1519, in signal_handler
    raise AirflowException("Task received SIGTERM signal")
airflow.exceptions.AirflowException: Task received SIGTERM signal
[2023-08-01T11:14:01.992+0000] {taskinstance.py:1350} INFO - Marking task as FAILED. dag_id=toronto_real_estate_etl, task_id=Extract, execution_date=20230728T000000, start_date=20230801T111216, end_date=20230801T111401
[2023-08-01T11:14:02.002+0000] {standard_task_runner.py:109} ERROR - Failed to execute job 71 for task Extract ((psycopg2.errors.ForeignKeyViolation) insert or update on table "task_fail" violates foreign key constraint "task_fail_ti_fkey"
DETAIL:  Key (dag_id, task_id, run_id, map_index)=(toronto_real_estate_etl, Extract, scheduled__2023-07-28T00:00:00+00:00, -1) is not present in table "task_instance".

[SQL: INSERT INTO task_fail (task_id, dag_id, run_id, map_index, start_date, end_date, duration) VALUES (%(task_id)s, %(dag_id)s, %(run_id)s, %(map_index)s, %(start_date)s, %(end_date)s, %(duration)s) RETURNING task_fail.id]
[parameters: {'task_id': 'Extract', 'dag_id': 'toronto_real_estate_etl', 'run_id': 'scheduled__2023-07-28T00:00:00+00:00', 'map_index': -1, 'start_date': datetime.datetime(2023, 8, 1, 11, 12, 16, 339731, tzinfo=Timezone('UTC')), 'end_date': datetime.datetime(2023, 8, 1, 11, 14, 1, 992331, tzinfo=Timezone('UTC')), 'duration': 105}]
(Background on this error at: https://sqlalche.me/e/14/gkpj); 442)
[2023-08-01T11:14:02.033+0000] {process_utils.py:79} INFO - Process psutil.Process(pid=442, status='terminated', exitcode=1, started='11:12:15') (442) terminated with exit code 1
