[2023-08-04T09:32:07.720+0000] {taskinstance.py:1103} INFO - Dependencies all met for dep_context=non-requeueable deps ti=<TaskInstance: toronto_real_estate_etl.Extract manual__2023-08-04T09:27:51.764069+00:00 [queued]>
[2023-08-04T09:32:07.727+0000] {taskinstance.py:1103} INFO - Dependencies all met for dep_context=requeueable deps ti=<TaskInstance: toronto_real_estate_etl.Extract manual__2023-08-04T09:27:51.764069+00:00 [queued]>
[2023-08-04T09:32:07.727+0000] {taskinstance.py:1308} INFO - Starting attempt 2 of 2
[2023-08-04T09:32:07.737+0000] {taskinstance.py:1327} INFO - Executing <Task(PythonOperator): Extract> on 2023-08-04 09:27:51.764069+00:00
[2023-08-04T09:32:07.742+0000] {standard_task_runner.py:57} INFO - Started process 160 to run task
[2023-08-04T09:32:07.745+0000] {standard_task_runner.py:84} INFO - Running: ['***', 'tasks', 'run', 'toronto_real_estate_etl', 'Extract', 'manual__2023-08-04T09:27:51.764069+00:00', '--job-id', '96', '--raw', '--subdir', 'DAGS_FOLDER/etl.py', '--cfg-path', '/tmp/tmpajsz4ufo']
[2023-08-04T09:32:07.746+0000] {standard_task_runner.py:85} INFO - Job 96: Subtask Extract
[2023-08-04T09:32:07.788+0000] {task_command.py:410} INFO - Running <TaskInstance: toronto_real_estate_etl.Extract manual__2023-08-04T09:27:51.764069+00:00 [running]> on host e5187b3c4256
[2023-08-04T09:32:07.841+0000] {taskinstance.py:1547} INFO - Exporting env vars: AIRFLOW_CTX_DAG_OWNER='***' AIRFLOW_CTX_DAG_ID='toronto_real_estate_etl' AIRFLOW_CTX_TASK_ID='Extract' AIRFLOW_CTX_EXECUTION_DATE='2023-08-04T09:27:51.764069+00:00' AIRFLOW_CTX_TRY_NUMBER='2' AIRFLOW_CTX_DAG_RUN_ID='manual__2023-08-04T09:27:51.764069+00:00'
[2023-08-04T09:32:07.842+0000] {Extract.py:31} INFO - https://www.kijiji.ca/b-apartments-condos/page-1/c37l1700273
[2023-08-04T09:33:38.331+0000] {local_task_job_runner.py:292} WARNING - State of this instance has been externally set to None. Terminating instance.
[2023-08-04T09:33:38.332+0000] {process_utils.py:135} INFO - Sending Signals.SIGTERM to group 160. PIDs of all processes in the group: [160]
[2023-08-04T09:33:38.332+0000] {process_utils.py:86} INFO - Sending the signal Signals.SIGTERM to group 160
[2023-08-04T09:33:38.332+0000] {taskinstance.py:1517} ERROR - Received SIGTERM. Terminating subprocesses.
[2023-08-04T09:33:38.338+0000] {taskinstance.py:1824} ERROR - Task failed with exception
Traceback (most recent call last):
  File "/home/airflow/.local/lib/python3.7/site-packages/airflow/operators/python.py", line 181, in execute
    return_value = self.execute_callable()
  File "/home/airflow/.local/lib/python3.7/site-packages/airflow/operators/python.py", line 198, in execute_callable
    return self.python_callable(*self.op_args, **self.op_kwargs)
  File "/opt/airflow/dags/src/main.py", line 22, in extract
    e.getListings(2,date)
  File "/opt/airflow/dags/src/Extract.py", line 50, in getListings
    time.sleep(3)
  File "/home/airflow/.local/lib/python3.7/site-packages/airflow/models/taskinstance.py", line 1519, in signal_handler
    raise AirflowException("Task received SIGTERM signal")
airflow.exceptions.AirflowException: Task received SIGTERM signal
[2023-08-04T09:33:38.343+0000] {taskinstance.py:1350} INFO - Marking task as FAILED. dag_id=toronto_real_estate_etl, task_id=Extract, execution_date=20230804T092751, start_date=20230804T093207, end_date=20230804T093338
[2023-08-04T09:33:38.351+0000] {standard_task_runner.py:109} ERROR - Failed to execute job 96 for task Extract ((psycopg2.errors.ForeignKeyViolation) insert or update on table "task_fail" violates foreign key constraint "task_fail_ti_fkey"
DETAIL:  Key (dag_id, task_id, run_id, map_index)=(toronto_real_estate_etl, Extract, manual__2023-08-04T09:27:51.764069+00:00, -1) is not present in table "task_instance".

[SQL: INSERT INTO task_fail (task_id, dag_id, run_id, map_index, start_date, end_date, duration) VALUES (%(task_id)s, %(dag_id)s, %(run_id)s, %(map_index)s, %(start_date)s, %(end_date)s, %(duration)s) RETURNING task_fail.id]
[parameters: {'task_id': 'Extract', 'dag_id': 'toronto_real_estate_etl', 'run_id': 'manual__2023-08-04T09:27:51.764069+00:00', 'map_index': -1, 'start_date': datetime.datetime(2023, 8, 4, 9, 32, 7, 721831, tzinfo=Timezone('UTC')), 'end_date': datetime.datetime(2023, 8, 4, 9, 33, 38, 343060, tzinfo=Timezone('UTC')), 'duration': 90}]
(Background on this error at: https://sqlalche.me/e/14/gkpj); 160)
[2023-08-04T09:33:38.385+0000] {process_utils.py:79} INFO - Process psutil.Process(pid=160, status='terminated', exitcode=1, started='09:32:07') (160) terminated with exit code 1
