[2023-09-01T11:20:14.971+0000] {taskinstance.py:1103} INFO - Dependencies all met for dep_context=non-requeueable deps ti=<TaskInstance: toronto_real_estate_etl.Transform manual__2023-09-01T11:18:38.418341+00:00 [queued]>
[2023-09-01T11:20:14.979+0000] {taskinstance.py:1103} INFO - Dependencies all met for dep_context=requeueable deps ti=<TaskInstance: toronto_real_estate_etl.Transform manual__2023-09-01T11:18:38.418341+00:00 [queued]>
[2023-09-01T11:20:14.979+0000] {taskinstance.py:1308} INFO - Starting attempt 1 of 1
[2023-09-01T11:20:14.989+0000] {taskinstance.py:1327} INFO - Executing <Task(PythonOperator): Transform> on 2023-09-01 11:18:38.418341+00:00
[2023-09-01T11:20:14.994+0000] {standard_task_runner.py:57} INFO - Started process 589 to run task
[2023-09-01T11:20:14.996+0000] {standard_task_runner.py:84} INFO - Running: ['***', 'tasks', 'run', 'toronto_real_estate_etl', 'Transform', 'manual__2023-09-01T11:18:38.418341+00:00', '--job-id', '129', '--raw', '--subdir', 'DAGS_FOLDER/etl.py', '--cfg-path', '/tmp/tmpxel195hf']
[2023-09-01T11:20:14.998+0000] {standard_task_runner.py:85} INFO - Job 129: Subtask Transform
[2023-09-01T11:20:15.031+0000] {task_command.py:410} INFO - Running <TaskInstance: toronto_real_estate_etl.Transform manual__2023-09-01T11:18:38.418341+00:00 [running]> on host e5187b3c4256
[2023-09-01T11:20:15.083+0000] {taskinstance.py:1547} INFO - Exporting env vars: AIRFLOW_CTX_DAG_OWNER='***' AIRFLOW_CTX_DAG_ID='toronto_real_estate_etl' AIRFLOW_CTX_TASK_ID='Transform' AIRFLOW_CTX_EXECUTION_DATE='2023-09-01T11:18:38.418341+00:00' AIRFLOW_CTX_TRY_NUMBER='1' AIRFLOW_CTX_DAG_RUN_ID='manual__2023-09-01T11:18:38.418341+00:00'
[2023-09-01T11:20:15.084+0000] {taskinstance.py:1824} ERROR - Task failed with exception
Traceback (most recent call last):
  File "/home/airflow/.local/lib/python3.7/site-packages/airflow/operators/python.py", line 181, in execute
    return_value = self.execute_callable()
  File "/home/airflow/.local/lib/python3.7/site-packages/airflow/operators/python.py", line 198, in execute_callable
    return self.python_callable(*self.op_args, **self.op_kwargs)
  File "/opt/airflow/dags/src/main.py", line 54, in transform
    t.saveToJson(date)
  File "/opt/airflow/dags/src/Transform.py", line 42, in saveToJson
    os.makedirs('/opt/airflow/dags/transformed/'+date)
  File "/usr/local/lib/python3.7/os.py", line 223, in makedirs
    mkdir(name, mode)
FileExistsError: [Errno 17] File exists: '/opt/airflow/dags/transformed/2023-09-01'
[2023-09-01T11:20:15.090+0000] {taskinstance.py:1350} INFO - Marking task as FAILED. dag_id=toronto_real_estate_etl, task_id=Transform, execution_date=20230901T111838, start_date=20230901T112014, end_date=20230901T112015
[2023-09-01T11:20:15.097+0000] {standard_task_runner.py:109} ERROR - Failed to execute job 129 for task Transform ([Errno 17] File exists: '/opt/airflow/dags/transformed/2023-09-01'; 589)
[2023-09-01T11:20:15.129+0000] {local_task_job_runner.py:225} INFO - Task exited with return code 1
[2023-09-01T11:20:15.147+0000] {taskinstance.py:2653} INFO - 0 downstream tasks scheduled from follow-on schedule check
